Workbook

Sheet Tổng hợp 
A1: Tên cuộc thi | B1: Lĩnh vực | C1: Đơn vị tổ chức | D1: Mô tả ngắn gọn | E1: Đối tượng tham gia | F1: Hình thức tham gia | G1: Cơ cấu vòng thi | H1: Cơ cấu giải thưởng | I1: Các mốc thời gian | J1: Mùa thi | K1: Deadline đăng ký | L1: Trạng thái | M1: Link nguồn chính thức
A2: ='Phân tích và chỉnh sửa'!B6 | B2: Khởi nghiệp | C2: ='Phân tích và chỉnh sửa'!B8 | D2: ='Phân tích và chỉnh sửa'!B9 | E2: ='Phân tích và chỉnh sửa'!B10 | F2: ='Phân tích và chỉnh sửa'!B11 | G2: ='Phân tích và chỉnh sửa'!B12 | H2: ='Phân tích và chỉnh sửa'!B13 | I2: ='Phân tích và chỉnh sửa'!B14 | J2: ='Phân tích và chỉnh sửa'!B15 | K2: ='Phân tích và chỉnh sửa'!B16 | L2: ='Phân tích và chỉnh sửa'!B17 | M2: ='Phân tích và chỉnh sửa'!B18
A3: ='Phân tích và chỉnh sửa'!B530 | B3: Khởi nghiệp | C3: ='Phân tích và chỉnh sửa'!B532 | D3: ='Phân tích và chỉnh sửa'!B533 | E3: ='Phân tích và chỉnh sửa'!B534 | F3: ='Phân tích và chỉnh sửa'!B535 | G3: ='Phân tích và chỉnh sửa'!B536 | H3: ='Phân tích và chỉnh sửa'!B537 | I3: ='Phân tích và chỉnh sửa'!B538 | J3: ='Phân tích và chỉnh sửa'!B539 | K3: ='Phân tích và chỉnh sửa'!B540 | L3: ='Phân tích và chỉnh sửa'!B541 | M3: ='Phân tích và chỉnh sửa'!B542
A4: ='Phân tích và chỉnh sửa'!B38 | B4: Khởi nghiệp | C4: ='Phân tích và chỉnh sửa'!B40 | D4: ='Phân tích và chỉnh sửa'!B41 | E4: ='Phân tích và chỉnh sửa'!B42 | F4: ='Phân tích và chỉnh sửa'!B43 | G4: ='Phân tích và chỉnh sửa'!B44 | H4: ='Phân tích và chỉnh sửa'!B45 | I4: ='Phân tích và chỉnh sửa'!B46 | J4: ='Phân tích và chỉnh sửa'!B47 | K4: ='Phân tích và chỉnh sửa'!B48 | L4: ='Phân tích và chỉnh sửa'!B49 | M4: ='Phân tích và chỉnh sửa'!B50
A5: ='Phân tích và chỉnh sửa'!B588 | B5: Khởi nghiệp | C5: ='Phân tích và chỉnh sửa'!B589 | D5: ='Phân tích và chỉnh sửa'!B577 | E5: ='Phân tích và chỉnh sửa'!B590 | F5: ='Phân tích và chỉnh sửa'!B591 | G5: ='Phân tích và chỉnh sửa'!B592 | H5: ='Phân tích và chỉnh sửa'!B593 | I5: ='Phân tích và chỉnh sửa'!B594 | J5: ='Phân tích và chỉnh sửa'!B595 | K5: ='Phân tích và chỉnh sửa'!B596 | L5: ='Phân tích và chỉnh sửa'!B597 | M5: ='Phân tích và chỉnh sửa'!B598
A6: ='Phân tích và chỉnh sửa'!B450 | B6: Khởi nghiệp | C6: ='Phân tích và chỉnh sửa'!B452 | D6: ='Phân tích và chỉnh sửa'!B453 | E6: ='Phân tích và chỉnh sửa'!B454 | F6: ='Phân tích và chỉnh sửa'!B455 | G6: ='Phân tích và chỉnh sửa'!B456 | H6: ='Phân tích và chỉnh sửa'!B457 | I6: ='Phân tích và chỉnh sửa'!B458 | J6: ='Phân tích và chỉnh sửa'!B459 | K6: ='Phân tích và chỉnh sửa'!B460 | L6: ='Phân tích và chỉnh sửa'!B461 | M6: ='Phân tích và chỉnh sửa'!B462
A7: ='Phân tích và chỉnh sửa'!B418 | B7: Khởi nghiệp | C7: ='Phân tích và chỉnh sửa'!B420 | D7: ='Phân tích và chỉnh sửa'!B421 | E7: ='Phân tích và chỉnh sửa'!B422 | F7: ='Phân tích và chỉnh sửa'!B423 | G7: ='Phân tích và chỉnh sửa'!B424 | H7: ='Phân tích và chỉnh sửa'!B425 | I7: ='Phân tích và chỉnh sửa'!B426 | J7: ='Phân tích và chỉnh sửa'!B427 | K7: ='Phân tích và chỉnh sửa'!B428 | L7: ='Phân tích và chỉnh sửa'!B429 | M7: ='Phân tích và chỉnh sửa'!B430
A8: ='Phân tích và chỉnh sửa'!B434 | B8: Khởi nghiệp | C8: ='Phân tích và chỉnh sửa'!B436 | D8: ='Phân tích và chỉnh sửa'!B437 | E8: ='Phân tích và chỉnh sửa'!B438 | F8: ='Phân tích và chỉnh sửa'!B439 | G8: ='Phân tích và chỉnh sửa'!B440 | H8: ='Phân tích và chỉnh sửa'!B441 | I8: ='Phân tích và chỉnh sửa'!B442 | J8: ='Phân tích và chỉnh sửa'!B443 | K8: ='Phân tích và chỉnh sửa'!B444 | L8: ='Phân tích và chỉnh sửa'!B445 | M8: ='Phân tích và chỉnh sửa'!B446
A9: ='Phân tích và chỉnh sửa'!B54 | B9: Khởi nghiệp | C9: ='Phân tích và chỉnh sửa'!B56 | D9: ='Phân tích và chỉnh sửa'!B57 | E9: ='Phân tích và chỉnh sửa'!B58 | F9: ='Phân tích và chỉnh sửa'!B59 | G9: ='Phân tích và chỉnh sửa'!B60 | H9: ='Phân tích và chỉnh sửa'!B61 | I9: ='Phân tích và chỉnh sửa'!B62 | J9: ='Phân tích và chỉnh sửa'!B63 | K9: ='Phân tích và chỉnh sửa'!B64 | L9: ='Phân tích và chỉnh sửa'!B65 | M9: ='Phân tích và chỉnh sửa'!B66
A10: ='Phân tích và chỉnh sửa'!B70 | B10: Khởi nghiệp | C10: ='Phân tích và chỉnh sửa'!B72 | D10: ='Phân tích và chỉnh sửa'!B73 | E10: ='Phân tích và chỉnh sửa'!B74 | F10: ='Phân tích và chỉnh sửa'!B75 | G10: ='Phân tích và chỉnh sửa'!B76 | H10: ='Phân tích và chỉnh sửa'!B77 | I10: ='Phân tích và chỉnh sửa'!B78 | J10: ='Phân tích và chỉnh sửa'!B79 | K10: ='Phân tích và chỉnh sửa'!B80 | L10: ='Phân tích và chỉnh sửa'!B81 | M10: ='Phân tích và chỉnh sửa'!B82
A11: ='Phân tích và chỉnh sửa'!B86 | B11: Khởi nghiệp | C11: ='Phân tích và chỉnh sửa'!B88 | D11: ='Phân tích và chỉnh sửa'!B89 | E11: ='Phân tích và chỉnh sửa'!B90 | F11: ='Phân tích và chỉnh sửa'!B91 | G11: ='Phân tích và chỉnh sửa'!B92 | H11: ='Phân tích và chỉnh sửa'!B93 | I11: ='Phân tích và chỉnh sửa'!B94 | J11: ='Phân tích và chỉnh sửa'!B95 | K11: ='Phân tích và chỉnh sửa'!B96 | L11: ='Phân tích và chỉnh sửa'!B97 | M11: ='Phân tích và chỉnh sửa'!B98
A12: ='Phân tích và chỉnh sửa'!B102 | B12: Khởi nghiệp | C12: ='Phân tích và chỉnh sửa'!B104 | D12: ='Phân tích và chỉnh sửa'!B105 | E12: ='Phân tích và chỉnh sửa'!B106 | F12: ='Phân tích và chỉnh sửa'!B107 | G12: ='Phân tích và chỉnh sửa'!B108 | H12: ='Phân tích và chỉnh sửa'!B109 | I12: ='Phân tích và chỉnh sửa'!B110 | J12: ='Phân tích và chỉnh sửa'!B111 | K12: ='Phân tích và chỉnh sửa'!B112 | L12: ='Phân tích và chỉnh sửa'!B113 | M12: ='Phân tích và chỉnh sửa'!B114
A13: ='Phân tích và chỉnh sửa'!B482 | B13: Khởi nghiệp | C13: ='Phân tích và chỉnh sửa'!B484 | D13: ='Phân tích và chỉnh sửa'!B485 | E13: ='Phân tích và chỉnh sửa'!B486 | F13: ='Phân tích và chỉnh sửa'!B487 | G13: ='Phân tích và chỉnh sửa'!B488 | H13: ='Phân tích và chỉnh sửa'!B489 | I13: ='Phân tích và chỉnh sửa'!B490 | J13: ='Phân tích và chỉnh sửa'!B491 | K13: ='Phân tích và chỉnh sửa'!B492 | L13: ='Phân tích và chỉnh sửa'!B493 | M13: ='Phân tích và chỉnh sửa'!B494
A14: ='Phân tích và chỉnh sửa'!B466 | B14: Khởi nghiệp | C14: ='Phân tích và chỉnh sửa'!B468 | D14: ='Phân tích và chỉnh sửa'!B469 | E14: ='Phân tích và chỉnh sửa'!B470 | F14: ='Phân tích và chỉnh sửa'!B471 | G14: ='Phân tích và chỉnh sửa'!B472 | H14: ='Phân tích và chỉnh sửa'!B473 | I14: ='Phân tích và chỉnh sửa'!B474 | J14: ='Phân tích và chỉnh sửa'!B475 | K14: ='Phân tích và chỉnh sửa'!B476 | L14: ='Phân tích và chỉnh sửa'!B477 | M14: ='Phân tích và chỉnh sửa'!B478
A15: ='Phân tích và chỉnh sửa'!B498 | B15: Khởi nghiệp | C15: ='Phân tích và chỉnh sửa'!B500 | D15: ='Phân tích và chỉnh sửa'!B501 | E15: ='Phân tích và chỉnh sửa'!B502 | F15: ='Phân tích và chỉnh sửa'!B503 | G15: ='Phân tích và chỉnh sửa'!B504 | H15: ='Phân tích và chỉnh sửa'!B505 | I15: ='Phân tích và chỉnh sửa'!B506 | J15: ='Phân tích và chỉnh sửa'!B507 | K15: ='Phân tích và chỉnh sửa'!B508 | L15: ='Phân tích và chỉnh sửa'!B509 | M15: ='Phân tích và chỉnh sửa'!B510
A16: ='Phân tích và chỉnh sửa'!B514 | B16: Khởi nghiệp | C16: ='Phân tích và chỉnh sửa'!B516 | D16: ='Phân tích và chỉnh sửa'!B517 | E16: ='Phân tích và chỉnh sửa'!B518 | F16: ='Phân tích và chỉnh sửa'!B519 | G16: ='Phân tích và chỉnh sửa'!B520 | H16: ='Phân tích và chỉnh sửa'!B521 | I16: ='Phân tích và chỉnh sửa'!B522 | J16: ='Phân tích và chỉnh sửa'!B523 | K16: ='Phân tích và chỉnh sửa'!B524 | L16: ='Phân tích và chỉnh sửa'!B525 | M16: ='Phân tích và chỉnh sửa'!B526
A17: ='Phân tích và chỉnh sửa'!B560 | B17: Khởi nghiệp | C17: ='Phân tích và chỉnh sửa'!B561 | D17: ='Phân tích và chỉnh sửa'!B549 | E17: ='Phân tích và chỉnh sửa'!B562 | F17: ='Phân tích và chỉnh sửa'!B563 | G17: ='Phân tích và chỉnh sửa'!B564 | H17: ='Phân tích và chỉnh sửa'!B565 | I17: ='Phân tích và chỉnh sửa'!B566 | J17: ='Phân tích và chỉnh sửa'!B567 | K17: ='Phân tích và chỉnh sửa'!B568 | L17: ='Phân tích và chỉnh sửa'!B569 | M17: ='Phân tích và chỉnh sửa'!B570
A18: ='Phân tích và chỉnh sửa'!B390 | B18: Khởi nghiệp | C18: ='Phân tích và chỉnh sửa'!B392 | D18: ='Phân tích và chỉnh sửa'!B393 | E18: ='Phân tích và chỉnh sửa'!B394 | F18: ='Phân tích và chỉnh sửa'!B395 | G18: ='Phân tích và chỉnh sửa'!B396 | H18: ='Phân tích và chỉnh sửa'!B397 | I18: ='Phân tích và chỉnh sửa'!B398 | J18: ='Phân tích và chỉnh sửa'!B399 | K18: ='Phân tích và chỉnh sửa'!B400 | L18: ='Phân tích và chỉnh sửa'!B401 | M18: ='Phân tích và chỉnh sửa'!B402
A19: ='Phân tích và chỉnh sửa'!B616 | B19: Khởi nghiệp | C19: ='Phân tích và chỉnh sửa'!B617 | D19: ='Phân tích và chỉnh sửa'!B605 | E19: ='Phân tích và chỉnh sửa'!B618 | F19: ='Phân tích và chỉnh sửa'!B619 | G19: ='Phân tích và chỉnh sửa'!B620 | H19: ='Phân tích và chỉnh sửa'!B621 | I19: ='Phân tích và chỉnh sửa'!B622 | J19: ='Phân tích và chỉnh sửa'!B623 | K19: ='Phân tích và chỉnh sửa'!B624 | L19: ='Phân tích và chỉnh sửa'!B625 | M19: ='Phân tích và chỉnh sửa'!B626
A20: Cuộc thi STARTUP ZONE | B20: Khởi nghiệp | M20: https://www.facebook.com/ClbNhanSuKhoiNghiep.ueh?locale=vi_VN
A21: ='Phân tích và chỉnh sửa'!B644 | B21: Khởi nghiệp | C21: ='Phân tích và chỉnh sửa'!B645 | D21: ='Phân tích và chỉnh sửa'!B633 | E21: ='Phân tích và chỉnh sửa'!B646 | F21: ='Phân tích và chỉnh sửa'!B647 | G21: ='Phân tích và chỉnh sửa'!B648 | H21: ='Phân tích và chỉnh sửa'!B637 | I21: ='Phân tích và chỉnh sửa'!B650 | J21: ='Phân tích và chỉnh sửa'!B651 | K21: ='Phân tích và chỉnh sửa'!B652 | L21: ='Phân tích và chỉnh sửa'!B653 | M21: ='Phân tích và chỉnh sửa'!B654
A22: ='Phân tích và chỉnh sửa'!B672 | B22: Khởi nghiệp | C22: ='Phân tích và chỉnh sửa'!B673 | D22: ='Phân tích và chỉnh sửa'!B661 | E22: ='Phân tích và chỉnh sửa'!B674 | F22: ='Phân tích và chỉnh sửa'!B675 | G22: ='Phân tích và chỉnh sửa'!B676 | H22: ='Phân tích và chỉnh sửa'!B677 | I22: ='Phân tích và chỉnh sửa'!B678 | J22: ='Phân tích và chỉnh sửa'!B679 | K22: ='Phân tích và chỉnh sửa'!B680 | L22: ='Phân tích và chỉnh sửa'!B681 | M22: ='Phân tích và chỉnh sửa'!B682
A23: ='Phân tích và chỉnh sửa'!B700 | B23: Khởi nghiệp | C23: ='Phân tích và chỉnh sửa'!B701 | D23: ='Phân tích và chỉnh sửa'!B689 | E23: ='Phân tích và chỉnh sửa'!B702 | F23: ='Phân tích và chỉnh sửa'!B703 | G23: ='Phân tích và chỉnh sửa'!B704 | H23: ='Phân tích và chỉnh sửa'!B705 | I23: ='Phân tích và chỉnh sửa'!B706 | J23: ='Phân tích và chỉnh sửa'!B707 | K23: ='Phân tích và chỉnh sửa'!B708 | L23: ='Phân tích và chỉnh sửa'!B709 | M23: ='Phân tích và chỉnh sửa'!B710
A24: ='Phân tích và chỉnh sửa'!B728 | B24: Khởi nghiệp | C24: ='Phân tích và chỉnh sửa'!B729 | D24: ='Phân tích và chỉnh sửa'!B717 | E24: ='Phân tích và chỉnh sửa'!B730 | F24: ='Phân tích và chỉnh sửa'!B731 | G24: ='Phân tích và chỉnh sửa'!B732 | H24: ='Phân tích và chỉnh sửa'!B733 | I24: ='Phân tích và chỉnh sửa'!B734 | J24: ='Phân tích và chỉnh sửa'!B735 | K24: ='Phân tích và chỉnh sửa'!B736 | L24: ='Phân tích và chỉnh sửa'!B737 | M24: ='Phân tích và chỉnh sửa'!B738
A25: ='Phân tích và chỉnh sửa'!B1858 | B25: Khởi nghiệp | C25: ='Phân tích và chỉnh sửa'!B1860 | D25: ='Phân tích và chỉnh sửa'!B1861 | E25: ='Phân tích và chỉnh sửa'!B1862 | F25: ='Phân tích và chỉnh sửa'!B1863 | G25: ='Phân tích và chỉnh sửa'!B1864 | H25: ='Phân tích và chỉnh sửa'!B1865 | I25: ='Phân tích và chỉnh sửa'!B1866 | J25: ='Phân tích và chỉnh sửa'!B1867 | K25: ='Phân tích và chỉnh sửa'!B1868 | L25: ='Phân tích và chỉnh sửa'!B1869 | M25: ='Phân tích và chỉnh sửa'!B1870
A26: ='Phân tích và chỉnh sửa'!B756 | B26: Khởi nghiệp | C26: ='Phân tích và chỉnh sửa'!B757 | D26: ='Phân tích và chỉnh sửa'!B745 | E26: ='Phân tích và chỉnh sửa'!B758 | F26: ='Phân tích và chỉnh sửa'!B759 | G26: ='Phân tích và chỉnh sửa'!B760 | H26: ='Phân tích và chỉnh sửa'!B761 | I26: ='Phân tích và chỉnh sửa'!B762 | J26: ='Phân tích và chỉnh sửa'!B763 | K26: ='Phân tích và chỉnh sửa'!B764 | L26: ='Phân tích và chỉnh sửa'!B765 | M26: ='Phân tích và chỉnh sửa'!B766
A27: ='Phân tích và chỉnh sửa'!B118 | B27: Khởi nghiệp | C27: ='Phân tích và chỉnh sửa'!B120 | D27: ='Phân tích và chỉnh sửa'!B121 | E27: ='Phân tích và chỉnh sửa'!B122 | F27: ='Phân tích và chỉnh sửa'!B123 | G27: ='Phân tích và chỉnh sửa'!B124 | H27: ='Phân tích và chỉnh sửa'!B125 | I27: ='Phân tích và chỉnh sửa'!B126 | J27: ='Phân tích và chỉnh sửa'!B127 | K27: ='Phân tích và chỉnh sửa'!B128 | L27: ='Phân tích và chỉnh sửa'!B129 | M27: ='Phân tích và chỉnh sửa'!B130
A28: ='Phân tích và chỉnh sửa'!B784 | B28: Khởi nghiệp | C28: ='Phân tích và chỉnh sửa'!B785 | D28: ='Phân tích và chỉnh sửa'!B773 | E28: ='Phân tích và chỉnh sửa'!B786 | F28: ='Phân tích và chỉnh sửa'!B787 | G28: ='Phân tích và chỉnh sửa'!B788 | H28: ='Phân tích và chỉnh sửa'!B789 | I28: ='Phân tích và chỉnh sửa'!B790 | J28: ='Phân tích và chỉnh sửa'!B791 | K28: ='Phân tích và chỉnh sửa'!B780 | L28: ='Phân tích và chỉnh sửa'!B793 | M28: ='Phân tích và chỉnh sửa'!B794
A29: ='Phân tích và chỉnh sửa'!B812 | B29: Khởi nghiệp | C29: ='Phân tích và chỉnh sửa'!B813 | D29: ='Phân tích và chỉnh sửa'!B801 | E29: ='Phân tích và chỉnh sửa'!B814 | F29: ='Phân tích và chỉnh sửa'!B815 | G29: ='Phân tích và chỉnh sửa'!B816 | H29: ='Phân tích và chỉnh sửa'!B817 | I29: ='Phân tích và chỉnh sửa'!B818 | J29: ='Phân tích và chỉnh sửa'!B819 | K29: ='Phân tích và chỉnh sửa'!B820 | L29: ='Phân tích và chỉnh sửa'!B821 | M29: ='Phân tích và chỉnh sửa'!B822
A30: ='Phân tích và chỉnh sửa'!B840 | B30: Khởi nghiệp | C30: ='Phân tích và chỉnh sửa'!B841 | D30: ='Phân tích và chỉnh sửa'!B829 | E30: ='Phân tích và chỉnh sửa'!B842 | F30: ='Phân tích và chỉnh sửa'!B843 | G30: ='Phân tích và chỉnh sửa'!B844 | H30: ='Phân tích và chỉnh sửa'!B845 | I30: ='Phân tích và chỉnh sửa'!B846 | J30: ='Phân tích và chỉnh sửa'!B847 | K30: ='Phân tích và chỉnh sửa'!B848 | L30: ='Phân tích và chỉnh sửa'!B849 | M30: ='Phân tích và chỉnh sửa'!B850
A31: ='Phân tích và chỉnh sửa'!B868 | B31: Khởi nghiệp | C31: ='Phân tích và chỉnh sửa'!B869 | D31: ='Phân tích và chỉnh sửa'!B857 | E31: ='Phân tích và chỉnh sửa'!B870 | F31: ='Phân tích và chỉnh sửa'!B871 | G31: ='Phân tích và chỉnh sửa'!B872 | H31: ='Phân tích và chỉnh sửa'!B873 | I31: ='Phân tích và chỉnh sửa'!B874 | J31: ='Phân tích và chỉnh sửa'!B875 | K31: ='Phân tích và chỉnh sửa'!B876 | L31: ='Phân tích và chỉnh sửa'!B877 | M31: ='Phân tích và chỉnh sửa'!B878
A32: ='Phân tích và chỉnh sửa'!B134 | B32: Khởi nghiệp | C32: ='Phân tích và chỉnh sửa'!B136 | D32: ='Phân tích và chỉnh sửa'!B137 | E32: ='Phân tích và chỉnh sửa'!B138 | F32: ='Phân tích và chỉnh sửa'!B139 | G32: ='Phân tích và chỉnh sửa'!B140 | H32: ='Phân tích và chỉnh sửa'!B141 | I32: ='Phân tích và chỉnh sửa'!B142 | J32: ='Phân tích và chỉnh sửa'!B143 | K32: ='Phân tích và chỉnh sửa'!B144 | L32: ='Phân tích và chỉnh sửa'!B145 | M32: ='Phân tích và chỉnh sửa'!B146
A33: ='Phân tích và chỉnh sửa'!B150 | B33: Khởi nghiệp | C33: ='Phân tích và chỉnh sửa'!B152 | D33: ='Phân tích và chỉnh sửa'!B153 | E33: ='Phân tích và chỉnh sửa'!B154 | F33: ='Phân tích và chỉnh sửa'!B155 | G33: ='Phân tích và chỉnh sửa'!B156 | H33: ='Phân tích và chỉnh sửa'!B157 | I33: ='Phân tích và chỉnh sửa'!B158 | J33: ='Phân tích và chỉnh sửa'!B159 | K33: ='Phân tích và chỉnh sửa'!B160 | L33: ='Phân tích và chỉnh sửa'!B161 | M33: ='Phân tích và chỉnh sửa'!B162
A34: ='Phân tích và chỉnh sửa'!B166 | B34: Khởi nghiệp | C34: ='Phân tích và chỉnh sửa'!B168 | D34: ='Phân tích và chỉnh sửa'!B169 | E34: ='Phân tích và chỉnh sửa'!B170 | F34: ='Phân tích và chỉnh sửa'!B171 | G34: ='Phân tích và chỉnh sửa'!B172 | H34: ='Phân tích và chỉnh sửa'!B173 | I34: ='Phân tích và chỉnh sửa'!B174 | J34: ='Phân tích và chỉnh sửa'!B175 | K34: ='Phân tích và chỉnh sửa'!B176 | L34: ='Phân tích và chỉnh sửa'!B177 | M34: ='Phân tích và chỉnh sửa'!B178
A35: ='Phân tích và chỉnh sửa'!B214 | B35: Khởi nghiệp | C35: ='Phân tích và chỉnh sửa'!B216 | D35: ='Phân tích và chỉnh sửa'!B217 | E35: ='Phân tích và chỉnh sửa'!B218 | F35: ='Phân tích và chỉnh sửa'!B219 | G35: ='Phân tích và chỉnh sửa'!B220 | H35: ='Phân tích và chỉnh sửa'!B221 | I35: ='Phân tích và chỉnh sửa'!B222 | J35: ='Phân tích và chỉnh sửa'!B223 | K35: ='Phân tích và chỉnh sửa'!B224 | L35: ='Phân tích và chỉnh sửa'!B225 | M35: ='Phân tích và chỉnh sửa'!B226
A36: ='Phân tích và chỉnh sửa'!B896 | B36: Business case | C36: ='Phân tích và chỉnh sửa'!B897 | D36: ='Phân tích và chỉnh sửa'!B885 | E36: ='Phân tích và chỉnh sửa'!B898 | F36: ='Phân tích và chỉnh sửa'!B899 | G36: ='Phân tích và chỉnh sửa'!B900 | H36: ='Phân tích và chỉnh sửa'!B901 | I36: ='Phân tích và chỉnh sửa'!B902 | J36: ='Phân tích và chỉnh sửa'!B903 | K36: ='Phân tích và chỉnh sửa'!B904 | L36: ='Phân tích và chỉnh sửa'!B905 | M36: ='Phân tích và chỉnh sửa'!B906
A37: ='Phân tích và chỉnh sửa'!B198 | B37: Business case | C37: ='Phân tích và chỉnh sửa'!B200 | D37: ='Phân tích và chỉnh sửa'!B201 | E37: ='Phân tích và chỉnh sửa'!B202 | F37: ='Phân tích và chỉnh sửa'!B203 | G37: ='Phân tích và chỉnh sửa'!B204 | H37: ='Phân tích và chỉnh sửa'!B205 | I37: ='Phân tích và chỉnh sửa'!B206 | J37: ='Phân tích và chỉnh sửa'!B207 | K37: ='Phân tích và chỉnh sửa'!B208 | L37: ='Phân tích và chỉnh sửa'!B209 | M37: ='Phân tích và chỉnh sửa'!B210
A38: ='Phân tích và chỉnh sửa'!B924 | B38: Business case | C38: ='Phân tích và chỉnh sửa'!B925 | D38: ='Phân tích và chỉnh sửa'!B913 | E38: ='Phân tích và chỉnh sửa'!B926 | F38: ='Phân tích và chỉnh sửa'!B927 | G38: ='Phân tích và chỉnh sửa'!B928 | H38: ='Phân tích và chỉnh sửa'!B929 | I38: ='Phân tích và chỉnh sửa'!B930 | J38: ='Phân tích và chỉnh sửa'!B931 | K38: ='Phân tích và chỉnh sửa'!B932 | L38: ='Phân tích và chỉnh sửa'!B933 | M38: ='Phân tích và chỉnh sửa'!B934
A39: ='Phân tích và chỉnh sửa'!B952 | B39: Business case | C39: ='Phân tích và chỉnh sửa'!B953 | D39: ='Phân tích và chỉnh sửa'!B941 | E39: ='Phân tích và chỉnh sửa'!B954 | F39: ='Phân tích và chỉnh sửa'!B955 | G39: ='Phân tích và chỉnh sửa'!B956 | H39: ='Phân tích và chỉnh sửa'!B957 | I39: ='Phân tích và chỉnh sửa'!B958 | J39: ='Phân tích và chỉnh sửa'!B959 | K39: ='Phân tích và chỉnh sửa'!B960 | L39: ='Phân tích và chỉnh sửa'!B961 | M39: ='Phân tích và chỉnh sửa'!B962
A40: ='Phân tích và chỉnh sửa'!B214 | B40: Business case | C40: ='Phân tích và chỉnh sửa'!B216 | D40: ='Phân tích và chỉnh sửa'!B217 | E40: ='Phân tích và chỉnh sửa'!B218 | F40: ='Phân tích và chỉnh sửa'!B219 | G40: ='Phân tích và chỉnh sửa'!B220 | H40: ='Phân tích và chỉnh sửa'!B221 | I40: ='Phân tích và chỉnh sửa'!B222 | J40: ='Phân tích và chỉnh sửa'!B223 | K40: ='Phân tích và chỉnh sửa'!B224 | L40: ='Phân tích và chỉnh sửa'!B225 | M40: ='Phân tích và chỉnh sửa'!B226
...

Sheet Phân tích và chỉnh sửa
A1: DỮ LIỆU PHÂN TÍCH (CÓ THỂ CHỈNH SỬA TRỰC TIẾP VÀO TỪNG Ô):
A2: Chỉnh sửa sẽ tự động lưu khi chuyển tab | Giá trị ở cột 'Giá Trị Sẽ Ghi Vào File' sẽ TỰ ĐỘNG CẬP NHẬT sang trang 'Tổng hợp'
A4: 🏆 CUỘC THI: KHỞI NGHIỆP CÙNG KAWAI 2026 [Liên kết tự động hàng #2 ở trang 'Tổng hợp ']
A5: Tên Cột Trong Excel | B5: Giá Trị Sẽ Ghi Vào File | C5: Nội dung từ web | D5: Link bài viết | E5: Ngày đăng bài (nếu có) | F5: Vị trí liên kết trang Tổng hợp
A6: Tên cuộc thi | B6: Khởi nghiệp cùng Kawai 2026 | C6: Khởi nghiệp cùng Kawai 2026 | D6: https://kbs.tec-ftu.com/ | E6: — | F6: ='Tổng hợp '!A2
A7: Lĩnh vực | B7: Khởi nghiệp | C7: Khởi nghiệp / Đổi mới sáng tạo | D7: https://kbs.tec-ftu.com/ | E7: — | F7: ='Tổng hợp '!B2
A8: Đơn vị tổ chức | B8: CLB Nhà Doanh nghiệp Tương lai (TEC) - Trường Đại học Ngoại thương | C8: CLB Nhà Doanh nghiệp Tương lai (TEC) - Trường Đại học Ngoại thương | D8: https://kbs.tec-ftu.com/ | E8: — | F8: ='Tổng hợp '!C2
A9: Mô tả ngắn gọn | B9: Cuộc thi ý tưởng khởi nghiệp sáng tạo dành cho startup Việt Nam 18–25 tuổi trên toàn thế giới, do CLB Nhà Doanh nghiệp Tương lai (TEC FTU) tổ chức. Mùa thi thứ 21 với đêm chung kết chủ đề "Tinh Quang" – nơi top 5 đội xuất sắc nhất pitching trước ban giám khảo, quỹ đầu tư và doanh nghiệp. | C9: Cuộc thi ý tưởng khởi nghiệp sáng tạo dành cho startup Việt Nam 18–25 tuổi trên toàn thế giới, do CLB Nhà Doanh nghiệp Tương lai (TEC FTU) tổ chức. Mùa thi thứ 21 với đêm chung kết chủ đề "Tinh Quang" – nơi top 5 đội xuất sắc nhất pitching trước ban giám khảo, quỹ đầu tư và doanh nghiệp. | D9: https://kbs.tec-ftu.com/ | E9: — | F9: ='Tổng hợp '!D2
A10: Đối tượng tham gia | B10: Startup Việt Nam trong độ tuổi 18–25 trên toàn thế giới | C10: Startup Việt Nam trong độ tuổi 18–25 trên toàn thế giới | D10: https://kbs.tec-ftu.com/ | E10: — | F10: ='Tổng hợp '!E2
A11: Hình thức tham gia | B11: Hybrid - Team (1-5 người) | C11: Hybrid - Team (1-5 người) | D11: https://kbs.tec-ftu.com/ | E11: — | F11: ='Tổng hợp '!F2
A12: Cơ cấu vòng thi | B12: Cuộc thi gồm 3 vòng: Vòng 1 và Vòng 2 là các vòng thử thách thực chiến (chi tiết không được cung cấp trong bài đăng); Vòng 3 'Tinh Quang' là Đêm Chung kết với phần pitching của TOP 5 đội xuất sắc trước Ban giám khảo, diễn ra tại Cung Văn hóa Lao động Hữu nghị Việt Xô ngày 08/07/2026. | C12: Cuộc thi gồm 3 vòng: Vòng 1 và Vòng 2 là các vòng thử thách thực chiến (chi tiết không được cung cấp trong bài đăng); Vòng 3 'Tinh Quang' là Đêm Chung kết với phần pitching của TOP 5 đội xuất sắc trước Ban giám khảo, diễn ra tại Cung Văn hóa Lao động Hữu nghị Việt Xô ngày 08/07/2026. | D12: https://kbs.tec-ftu.com/ | E12: — | F12: ='Tổng hợp '!G2
A13: Cơ cấu giải thưởng | B13: Chưa công bố chi tiết; ngôi vị Quán quân mùa thi thứ 21 được trao tại Đêm Chung kết | C13: Chưa công bố chi tiết; ngôi vị Quán quân mùa thi thứ 21 được trao tại Đêm Chung kết | D13: https://kbs.tec-ftu.com/ | E13: — | F13: ='Tổng hợp '!H2
A14: Các mốc thời gian | B14: Vòng 1: Nộp hồ sơ & Ý tưởng ban đầu: Không rõ | Vòng 2: Thử thách thực chiến: Không rõ | Vòng 3 - Tinh Quang: Đêm Chung kết: 2026-07-08 | C14: Vòng 1: Nộp hồ sơ & Ý tưởng ban đầu: Không rõ | Vòng 2: Thử thách thực chiến: Không rõ | Vòng 3 - Tinh Quang: Đêm Chung kết: 2026-07-08 | D14: https://kbs.tec-ftu.com/ | E14: — | F14: ='Tổng hợp '!I2
A15: Mùa thi | B15: Mùa thi thứ 21 (2026) | C15: Mùa thi thứ 21 (2026) | D15: https://kbs.tec-ftu.com/ | E15: — | F15: ='Tổng hợp '!J2
A16: Deadline đăng ký | B16: 2026-07-08 | C16: 2026-07-08 | D16: https://kbs.tec-ftu.com/ | E16: — | F16: ='Tổng hợp '!K2
A17: Trạng thái | B17: Đã kết thúc | C17: Đã kết thúc | D17: https://kbs.tec-ftu.com/ | E17: — | F17: ='Tổng hợp '!L2
A18: Link nguồn chính thức | B18: https://kbs.tec-ftu.com/ | C18: https://kbs.tec-ftu.com/ | D18: https://kbs.tec-ftu.com/ | E18: — | F18: ='Tổng hợp '!M2
A19: Tên cuộc thi | B19: Khởi nghiệp cùng Kawai 2026 | C19: Khởi nghiệp cùng Kawai 2026 | D19: https://kbs.tec-ftu.com/ | E19: — | F19: ='Tổng hợp '!A2
A20: Lĩnh vực | B20: Khởi nghiệp | C20: Khởi nghiệp / Đổi mới sáng tạo | D20: https://kbs.tec-ftu.com/ | E20: — | F20: ='Tổng hợp '!B2
A21: Đơn vị tổ chức | B21: CLB Nhà Doanh nghiệp Tương lai (TEC) - Trường Đại học Ngoại thương | C21: CLB Nhà Doanh nghiệp Tương lai (TEC) - Trường Đại học Ngoại thương | D21: https://kbs.tec-ftu.com/ | E21: — | F21: ='Tổng hợp '!C2
A22: Đối tượng tham gia | B22: Startup Việt Nam trong độ tuổi 18–25 trên toàn thế giới | C22: Startup Việt Nam trong độ tuổi 18–25 trên toàn thế giới | D22: https://kbs.tec-ftu.com/ | E22: — | F22: ='Tổng hợp '!E2
A23: Hình thức tham gia | B23: Thi theo đội; nộp ý tưởng khởi nghiệp, trải qua các vòng thử thách thực chiến và pitching trực tiếp tại đêm chung kết | C23: Thi theo đội; nộp ý tưởng khởi nghiệp, trải qua các vòng thử thách thực chiến và pitching trực tiếp tại đêm chung kết | D23: https://kbs.tec-ftu.com/ | E23: — | F23: ='Tổng hợp '!F2
A24: Cơ cấu vòng thi | B24: Vòng 1; Vòng 2; Vòng 3 (Tinh Quang – Đêm Chung kết): Top 5 đội xuất sắc pitching trước Ban giám khảo | C24: Vòng 1; Vòng 2; Vòng 3 (Tinh Quang – Đêm Chung kết): Top 5 đội xuất sắc pitching trước Ban giám khảo | D24: https://kbs.tec-ftu.com/ | E24: — | F24: ='Tổng hợp '!G2
A25: Cơ cấu giải thưởng | B25: Chưa công bố chi tiết; ngôi vị Quán quân mùa thi thứ 21 được trao tại Đêm Chung kết | C25: Chưa công bố chi tiết; ngôi vị Quán quân mùa thi thứ 21 được trao tại Đêm Chung kết | D25: https://kbs.tec-ftu.com/ | E25: — | F25: ='Tổng hợp '!H2
A26: Các mốc thời gian | B26: Đêm Chung kết: 08/07/2026 tại Cung Văn hóa Lao động Hữu nghị Việt Xô, 91 Trần Hưng Đạo, Hoàn Kiếm, Hà Nội | C26: Đêm Chung kết: 08/07/2026 tại Cung Văn hóa Lao động Hữu nghị Việt Xô, 91 Trần Hưng Đạo, Hoàn Kiếm, Hà Nội | D26: https://kbs.tec-ftu.com/ | E26: — | F26: ='Tổng hợp '!I2
A27: Mùa thi | B27: Mùa thi thứ 21 (2026) | C27: Mùa thi thứ 21 (2026) | D27: https://kbs.tec-ftu.com/ | E27: — | F27: ='Tổng hợp '!J2
A28: Deadline đăng ký | C28: (Chưa có trích dẫn từ web) | D28: https://kbs.tec-ftu.com/ | E28: — | F28: ='Tổng hợp '!K2
A29: Trạng thái | B29: Đang mở đăng ký tham dự Đêm Chung kết (vòng 3) | C29: Đang mở đăng ký tham dự Đêm Chung kết (vòng 3) | D29: https://kbs.tec-ftu.com/ | E29: — | F29: ='Tổng hợp '!L2
A30: Link nguồn chính thức | B30: http://kbs.tec-ftu.com/ | C30: http://kbs.tec-ftu.com/ | D30: https://kbs.tec-ftu.com/ | E30: — | F30: ='Tổng hợp '!M2
D31: https://kbs.tec-ftu.com/
D32: https://kbs.tec-ftu.com/
D33: https://kbs.tec-ftu.com/
D34: https://kbs.tec-ftu.com/
A36: 🏆 CUỘC THI: KHỞI NGHIỆP TRẺ 2026 [Liên kết tự động hàng #4 ở trang 'Tổng hợp ']
A37: Tên Cột Trong Excel | B37: Giá Trị Sẽ Ghi Vào File | C37: Nội dung từ web | D37: Link bài viết | E37: Ngày đăng bài (nếu có) | F37: Vị trí liên kết trang Tổng hợp
A38: Tên cuộc thi | B38: Khởi Nghiệp Trẻ 2026 | C38: Khởi Nghiệp Trẻ 2026 | D38: https://bsc-aof.com/index.php/khoi-nghiep-tre-2026/ | E38: 23/09/2026 | F38: ='Tổng hợp '!A4
A39: Lĩnh vực | B39: Khởi nghiệp | C39: Khởi nghiệp / Kinh doanh | D39: https://bsc-aof.com/index.php/khoi-nghiep-tre-2026/ | E39: 23/09/2026 | F39: ='Tổng hợp '!B4
A40: Đơn vị tổ chức | B40: Câu lạc bộ Kỹ năng Kinh doanh (BSC) – Học viện Tài chính; hỗ trợ bởi Liên chi đoàn Khoa Tài chính Doanh nghiệp và Đoàn Thanh niên Học viện Tài chính | C40: Câu lạc bộ Kỹ năng Kinh doanh (BSC) – Học viện Tài chính; hỗ trợ bởi Liên chi đoàn Khoa Tài chính Doanh nghiệp và Đoàn Thanh niên Học viện Tài chính | D40: https://bsc-aof.com/index.php/khoi-nghiep-tre-2026/ | E40: 23/09/2026 | F40: ='Tổng hợp '!C4
A41: Mô tả ngắn gọn | B41: Cuộc thi sáng tạo ý tưởng khởi nghiệp dành cho sinh viên Học viện Tài chính, tiền thân là cuộc thi "Khởi nghiệp trong tôi", nhằm tìm kiếm và phát triển sinh viên có đam mê kinh doanh, khởi nghiệp. | C41: Cuộc thi sáng tạo ý tưởng khởi nghiệp dành cho sinh viên Học viện Tài chính, tiền thân là cuộc thi "Khởi nghiệp trong tôi", nhằm tìm kiếm và phát triển sinh viên có đam mê kinh doanh, khởi nghiệp. | D41: https://bsc-aof.com/index.php/khoi-nghiep-tre-2026/ | E41: 23/09/2026 | F41: ='Tổng hợp '!D4
A42: Đối tượng tham gia | B42: Sinh viên Học viện Tài chính | C42: Sinh viên Học viện Tài chính | D42: https://bsc-aof.com/index.php/khoi-nghiep-tre-2026/ | E42: 23/09/2026 | F42: ='Tổng hợp '!E4
...

Sheet Startup 
A1: Tên cuộc thi | B1: Lĩnh vực | C1: Đơn vị tổ chức | D1: Mô tả ngắn gọn | E1: Đối tượng tham gia | F1: Hình thức tham gia | G1: Cơ cấu vòng thi | H1: Cơ cấu giải thưởng | I1: Các mốc thời gian | J1: Mùa thi | K1: Deadline đăng ký | L1: Trạng thái | M1: Link nguồn chính thức
A2: Khởi nghiệp cùng Kawai | B2: Khởi nghiệp
A3: Khởi nghiệp kinh doanh | B3: Khởi nghiệp
A4: Khởi nghiệp trẻ | B4: Khởi nghiệp
A5: Khởi nghiệp sinh viên - Biz4Good | B5: Khởi nghiệp
A6: Khởi nghiệp tạo tác động xã hội - I impACT | B6: Khởi nghiệp
A7: Thử thách sáng tạo xã hội Việt Nam | B7: Khởi nghiệp
A8: KMAC - FTU Global Innovative Ideads Contest | B8: Khởi nghiệp
A9: Khởi nghiệp sáng tạo "RnD TO STARTUP" | B9: Khởi nghiệp
A10: Startup Runway | B10: Khởi nghiệp
A11: Ra khơi | B11: Khởi nghiệp
A12: Startup Program | B12: Khởi nghiệp
A13: Ý tưởng kinh doanh | B13: Khởi nghiệp
... A33: Giải thưởng Sáng tạo Tương lai – VietFuture Awards | B33: Khởi nghiệp
